Workbook

Sheet Setup_Control
B2: NON-CORPORATE ENTITY FINANCIAL STATEMENTS - CONTROL PANEL
B3: Configure entity details, reporting year, and master heads (Select Yes/No for each head)
B5: 1. Basic Entity & Period Settings
B6: Entity / Business Name: | C6: M/s. ABC Enterprises
B7: Constitution / Entity Type: | C7: Proprietorship
B8: Current Financial Year Ended (CY): | C8: 31 March 2026
B9: Include Previous Year (PY) Column in Reports?: | C9: No
B10: Previous Financial Year Ended (PY): | C10: 31 March 2025
B11: Reporting Currency Unit: | C11: Amount in ₹
B13: 2. Master Balance Sheet Line Items (Yes = Include in Report, No = Remove from Balance Sheet)
B14: Category / Classification | C14: Financial Statement Line Item | D14: Include? (Yes/No) | E14: Note Ref | F14: Status in Financial Report
B15: Non-Current Assets | C15: Property, Plant and Equipment (PPE) | D15: Yes | E15: Note 11 | F15: =IF(D15="Yes", "Active in Balance Sheet", "Hidden / Excluded") -> Active in Balance Sheet
B16: Non-Current Assets | C16: Capital work-in-progress (CWIP) | D16: No | E16: Note 11 | F16: =IF(D16="Yes", "Active in Balance Sheet", "Hidden / Excluded") -> Hidden / Excluded
B17: Non-Current Assets | C17: Non-current investments | D17: Yes | E17: Note 12 | F17: =IF(D17="Yes", "Active in Balance Sheet", "Hidden / Excluded") -> Active in Balance Sheet
B18: Non-Current Assets | C18: Long-term loans and advances | D18: No | E18: Note 13 | F18: =IF(D18="Yes", "Active in Balance Sheet", "Hidden / Excluded") -> Hidden / Excluded
B19: Non-Current Assets | C19: Other non-current assets | D19: No | E19: Note 14 | F19: =IF(D19="Yes", "Active in Balance Sheet", "Hidden / Excluded") -> Hidden / Excluded
B20: Current Assets | C20: Current investments | D20: No | E20: Note 12 | F20: =IF(D20="Yes", "Active in Balance Sheet", "Hidden / Excluded") -> Hidden / Excluded
B21: Current Assets | C21: Inventories (Stock in Hand) | D21: Yes | E21: Note 15 | F21: =IF(D21="Yes", "Active in Balance Sheet", "Hidden / Excluded") -> Active in Balance Sheet
B22: Current Assets | C22: Trade receivables (Sundry Debtors) | D22: Yes | E22: Note 16 | F22: =IF(D22="Yes", "Active in Balance Sheet", "Hidden / Excluded") -> Active in Balance Sheet
B23: Current Assets | C23: Cash and bank balances | D23: Yes | E23: Note 17 | F23: =IF(D23="Yes", "Active in Balance Sheet", "Hidden / Excluded") -> Active in Balance Sheet
B24: Current Assets | C24: Short-term loans and advances | D24: Yes | E24: Note 13 | F24: =IF(D24="Yes", "Active in Balance Sheet", "Hidden / Excluded") -> Active in Balance Sheet
B25: Current Assets | C25: Other current assets | D25: No | E25: Note 18 | F25: =IF(D25="Yes", "Active in Balance Sheet", "Hidden / Excluded") -> Hidden / Excluded
B26: Equity | C26: Owners Capital Account | D26: Yes | E26: Note 3 | F26: =IF(D26="Yes", "Active in Balance Sheet", "Hidden / Excluded") -> Active in Balance Sheet
... B34: Current Liabilities | C34: Short-term provisions | D34: Yes | E34: Note 8 | F34: =IF(D34="Yes", "Active in Balance Sheet", "Hidden / Excluded") -> Active in Balance Sheet

Sheet Statement_of_P&L
A1: =Setup_Control!C6 -> M/s. ABC Enterprises
A2: ="Statement of Profit and Loss for the year ended " & Setup_Control!C8 -> Statement of Profit and Loss for the year ended 31 March 2026
D3: ="(" & Setup_Control!C11 & ")" -> (Amount in ₹)
B4: Particulars | C4: Note | D4: =Setup_Control!C8 -> 31 March 2026 | E4: =IF(Setup_Control!C9="Yes", Setup_Control!C10, "")
A5: I | B5: Revenue from operations | C5: 19 | D5: 0 | E5: =IF(Setup_Control!C9="Yes", 0, "")
A6: II | B6: Other Income | C6: 20 | D6: =PL_Notes!D52 -> 0 | E6: =IF(Setup_Control!C9="Yes", 0, "")
A7: III | B7: Total Income (I + II) | D7: =D5+D6 -> 0 | E7: =IF(Setup_Control!C9="Yes", E5+E6, "")
A8: IV | B8: EXPENSES:
A9: (a) | B9: Cost of goods sold / Raw Material Consumed | C9: 21 | D9: =BS_Notes!F58 -> 0 | E9: =IF(Setup_Control!C9="Yes", 0, "")
A10: (b) | B10: Employee benefits expense | C10: 22 | D10: =PL_Notes!D22 -> 0 | E10: =IF(Setup_Control!C9="Yes", 0, "")
A11: (c) | B11: Finance costs | C11: 23 | D11: =PL_Notes!D32 -> 0 | E11: =IF(Setup_Control!C9="Yes", 0, "")
A12: (d) | B12: Depreciation and amortization expense | C12: 24 | D12: 0 | E12: =IF(Setup_Control!C9="Yes", 0, "")
A13: (e) | B13: Other expenses | C13: 25 | D13: =PL_Notes!D42 -> 0 | E13: =IF(Setup_Control!C9="Yes", 0, "")
B14: Total Expenses (IV) | D14: =SUM(D9:D13) -> 0 | E14: =IF(Setup_Control!C9="Yes", SUM(E9:E13), "")
A15: V | B15: Profit / (Loss) before remuneration and tax (III - IV) | D15: =D7-D14 -> 0 | E15: =IF(Setup_Control!C9="Yes", E7-E14, "")
A16: VI | B16: =IF(Setup_Control!C7="Proprietorship", "Remuneration (Not Applicable for Proprietor)", "Partners Remuneration*") -> Remuneration (Not Applicable for Proprietor) | D16: 0 | E16: =IF(Setup_Control!C9="Yes", 0, "")
A17: VII | B17: Profit Before Tax (V - VI) | D17: =D15-D16 -> 0 | E17: =IF(Setup_Control!C9="Yes", E15-E16, "")
A18: VIII | B18: Tax Expense (Current Income Tax) | D18: 0 | E18: =IF(Setup_Control!C9="Yes", 0, "")
A19: IX | B19: Profit / (Loss) for the year transferred to Capital Account (VII - VIII) | D19: =D17-D18 -> 0 | E19: =IF(Setup_Control!C9="Yes", E17-E18, "")

Sheet Balance_Sheet
A1: =Setup_Control!C6 -> M/s. ABC Enterprises
A2: ="Balance Sheet as at " & Setup_Control!C8 -> Balance Sheet as at 31 March 2026
D3: ="(" & Setup_Control!C11 & ")" -> (Amount in ₹)
B4: Particulars | C4: Note | D4: =Setup_Control!C8 -> 31 March 2026 | E4: =IF(Setup_Control!C9="Yes", Setup_Control!C10, "")
A5: I | B5: EQUITY AND LIABILITIES
A6: 1 | B6: Owners Funds
A7: (a) | B7: =IF(Setup_Control!D26="Yes", IF(Setup_Control!C7="Proprietorship", "Owners Capital Account", "Partners Capital Account"), "") -> Owners Capital Account | C7: =IF(Setup_Control!D26="Yes", 3, "") -> 3 | D7: =IF(Setup_Control!D26="Yes", BS_Notes!C9, 0) -> #NAME? | E7: =IF(AND(Setup_Control!C9="Yes", Setup_Control!D26="Yes"), 0, "")
A8: (b) | B8: =IF(Setup_Control!D27="Yes", "Reserves and surplus", "") -> Reserves and surplus | C8: =IF(Setup_Control!D27="Yes", 4, "") -> 4 | D8: =IF(Setup_Control!D27="Yes", 0, 0) -> 0 | E8: =IF(AND(Setup_Control!C9="Yes", Setup_Control!D27="Yes"), 0, "")
B9: Sub-total: Owners Funds | D9: =D7+D8 -> #NAME? | E9: =IF(Setup_Control!C9="Yes", E7+E8, "")
A10: 2 | B10: Non-current liabilities
A11: (a) | B11: =IF(Setup_Control!D28="Yes", "Long-term borrowings (Term Loans)", "") -> Long-term borrowings (Term Loans) | C11: =IF(Setup_Control!D28="Yes", "5A", "") -> 5A | D11: =IF(Setup_Control!D28="Yes", BS_Notes!C16, 0) -> 0 | E11: =IF(AND(Setup_Control!C9="Yes", Setup_Control!D28="Yes"), 0, "")
A12: (b) | B12: =IF(Setup_Control!D29="Yes", "Other long-term liabilities", "") | C12: =IF(Setup_Control!D29="Yes", 7, "") | D12: 0 | E12: =IF(AND(Setup_Control!C9="Yes", Setup_Control!D29="Yes"), 0, "")
A13: (c) | B13: =IF(Setup_Control!D30="Yes", "Long-term provisions", "") | C13: =IF(Setup_Control!D30="Yes", 8, "") | D13: 0 | E13: =IF(AND(Setup_Control!C9="Yes", Setup_Control!D30="Yes"), 0, "")
B14: Sub-total: Non-current liabilities | D14: =SUM(D11:D13) -> 0 | E14: =IF(Setup_Control!C9="Yes", SUM(E11:E13), "")
A15: 3 | B15: Current liabilities
A16: (a) | B16: =IF(Setup_Control!D31="Yes", "Short-term borrowings (CC / OD / Loans)", "") -> Short-term borrowings (CC / OD / Loans) | C16: =IF(Setup_Control!D31="Yes", "5B", "") -> 5B | D16: =IF(Setup_Control!D31="Yes", BS_Notes!C23, 0) -> 0 | E16: =IF(AND(Setup_Control!C9="Yes", Setup_Control!D31="Yes"), 0, "")
A17: (b) | B17: =IF(Setup_Control!D32="Yes", "Trade payables (Sundry Creditors)", "") -> Trade payables (Sundry Creditors) | C17: =IF(Setup_Control!D32="Yes", 9, "") -> 9 | D17: =IF(Setup_Control!D32="Yes", BS_Notes!C30, 0) -> 0 | E17: =IF(AND(Setup_Control!C9="Yes", Setup_Control!D32="Yes"), 0, "")
A18: (c) | B18: =IF(Setup_Control!D33="Yes", "Other current liabilities", "") -> Other current liabilities | C18: =IF(Setup_Control!D33="Yes", 10, "") -> 10 | D18: =IF(Setup_Control!D33="Yes", BS_Notes!C37, 0) -> 0 | E18: =IF(AND(Setup_Control!C9="Yes", Setup_Control!D33="Yes"), 0, "")
A19: (d) | B19: =IF(Setup_Control!D34="Yes", "Short-term provisions", "") -> Short-term provisions | C19: =IF(Setup_Control!D34="Yes", 8, "") -> 8 | D19: 0 | E19: =IF(AND(Setup_Control!C9="Yes", Setup_Control!D34="Yes"), 0, "")
B20: Sub-total: Current liabilities | D20: =SUM(D16:D19) -> 0 | E20: =IF(Setup_Control!C9="Yes", SUM(E16:E19), "")
B21: TOTAL EQUITY AND LIABILITIES | D21: =D9+D14+D20 -> #NAME? | E21: =IF(Setup_Control!C9="Yes", E9+E14+E20, "")
A23: II | B23: ASSETS
A24: 1 | B24: Non-current assets
A25: (a) | B25: =IF(Setup_Control!D15="Yes", "Property, Plant and Equipment (PPE)", "") -> Property, Plant and Equipment (PPE) | C25: =IF(Setup_Control!D15="Yes", 11, "") -> 11 | D25: =IF(Setup_Control!D15="Yes", BS_Notes!F45, 0) -> #NAME? | E25: =IF(AND(Setup_Control!C9="Yes", Setup_Control!D15="Yes"), 0, "")
A26: (b) | B26: =IF(Setup_Control!D16="Yes", "Capital work-in-progress (CWIP)", "") | C26: =IF(Setup_Control!D16="Yes", 11, "") | D26: 0 | E26: =IF(AND(Setup_Control!C9="Yes", Setup_Control!D16="Yes"), 0, "")
A27: (c) | B27: =IF(Setup_Control!D17="Yes", "Non-current investments", "") -> Non-current investments | C27: =IF(Setup_Control!D17="Yes", 12, "") -> 12 | D27: =IF(Setup_Control!D17="Yes", BS_Notes!F52, 0) -> 0 | E27: =IF(AND(Setup_Control!C9="Yes", Setup_Control!D17="Yes"), 0, "")
A28: (d) | B28: =IF(Setup_Control!D18="Yes", "Long-term loans and advances", "") | C28: =IF(Setup_Control!D18="Yes", 13, "") | D28: 0 | E28: =IF(AND(Setup_Control!C9="Yes", Setup_Control!D18="Yes"), 0, "")
A29: (e) | B29: =IF(Setup_Control!D19="Yes", "Other non-current assets", "") | C29: =IF(Setup_Control!D19="Yes", 14, "") | D29: 0 | E29: =IF(AND(Setup_Control!C9="Yes", Setup_Control!D19="Yes"), 0, "")
B30: Sub-total: Non-current assets | D30: =SUM(D25:D29) -> #NAME? | E30: =IF(Setup_Control!C9="Yes", SUM(E25:E29), "")
A31: 2 | B31: Current assets
A32: (a) | B32: =IF(Setup_Control!D20="Yes", "Current investments", "") | C32: =IF(Setup_Control!D20="Yes", 12, "") | D32: 0 | E32: =IF(AND(Setup_Control!C9="Yes", Setup_Control!D20="Yes"), 0, "")
A33: (b) | B33: =IF(Setup_Control!D21="Yes", "Inventories (Stock in Hand)", "") -> Inventories (Stock in Hand) | C33: =IF(Setup_Control!D21="Yes", 15, "") -> 15 | D33: =IF(Setup_Control!D21="Yes", BS_Notes!F59, 0) -> 0 | E33: =IF(AND(Setup_Control!C9="Yes", Setup_Control!D21="Yes"), 0, "")
A34: (c) | B34: =IF(Setup_Control!D22="Yes", "Trade receivables (Sundry Debtors)", "") -> Trade receivables (Sundry Debtors) | C34: =IF(Setup_Control!D22="Yes", 16, "") -> 16 | D34: =IF(Setup_Control!D22="Yes", BS_Notes!F66, 0) -> #NAME? | E34: =IF(AND(Setup_Control!C9="Yes", Setup_Control!D22="Yes"), 0, "")
A35: (d) | B35: =IF(Setup_Control!D23="Yes", "Cash and bank balances", "") -> Cash and bank balances | C35: =IF(Setup_Control!D23="Yes", 17, "") -> 17 | D35: =IF(Setup_Control!D23="Yes", BS_Notes!F78, 0) -> #NAME? | E35: =IF(AND(Setup_Control!C9="Yes", Setup_Control!D23="Yes"), 0, "")
A36: (e) | B36: =IF(Setup_Control!D24="Yes", "Short-term loans and advances", "") -> Short-term loans and advances | C36: =IF(Setup_Control!D24="Yes", 13, "") -> 13 | D36: =IF(Setup_Control!D24="Yes", BS_Notes!F85, 0) -> 0 | E36: =IF(AND(Setup_Control!C9="Yes", Setup_Control!D24="Yes"), 0, "")
A37: (f) | B37: =IF(Setup_Control!D25="Yes", "Other current assets", "") | C37: =IF(Setup_Control!D25="Yes", 18, "") | D37: 0 | E37: =IF(AND(Setup_Control!C9="Yes", Setup_Control!D25="Yes"), 0, "")
B38: Sub-total: Current assets | D38: =SUM(D32:D37) -> #NAME? | E38: =IF(Setup_Control!C9="Yes", SUM(E32:E37), "")
B39: TOTAL ASSETS | D39: =D30+D38 -> #NAME? | E39: =IF(Setup_Control!C9="Yes", E30+E38, "")
B41: BALANCE CHECK VERIFICATION: | D41: =IF(ROUND(D21-D39,2)=0,"BALANCED ✓","DIFF: " & TEXT(D21-D39,"#,##0.00")) -> #NAME? | E41: =IF(Setup_Control!C9="Yes", IF(ROUND(E21-E39,2)=0,"BALANCED ✓","DIFF: " & TEXT(E21-E39,"#,##0.00")), "")

Sheet BS_Notes
A1: =Setup_Control!C6 -> M/s. ABC Enterprises
A2: ="Balance Sheet Item Ledgers (Horizontal Dr. / Cr. Format) for Financial Year Ended " & Setup_Control!C8 -> Balance Sheet Item Ledgers (Horizontal Dr. / Cr. Format) for Financial Year Ended 31 March 2026
A4: Owners Capital Account (Note 3)
A5: Dr. (Debit Side) | D5: Cr. (Credit Side)
A6: Date | B6: Particulars (Debit) | C6: Amount (₹) | D6: Date | E6: Particulars (Credit) | F6: Amount (₹)
B7: To Drawings during the year | C7: 0 | E7: By Balance b/d (Opening Capital) | F7: 0
B8: To Income Tax paid on behalf of Owner | C8: 0 | E8: By Additional Capital Introduced | F8: 0
B9: To Balance c/d (Closing Owners Capital) | C9: =F9-C7-C8 -> #NAME? | E9: By Net Profit for the year (from Statement of P&L) | F9: =Statement_of_P&L!D19 -> #NAME?
B10: Total Debit: | C10: =SUM(C7:C9) -> #NAME? | E10: Total Credit: | F10: =SUM(F7:F9) -> #NAME?
A12: Long-Term Borrowings (Term Loans Ledger) (Note 5A)
A13: Dr. (Debit Side) | D13: Cr. (Credit Side)
A14: Date | B14: Particulars (Debit) | C14: Amount (₹) | D14: Date | E14: Particulars (Credit) | F14: Amount (₹)
B15: To Principal Repayment during year | C15: 0 | E15: By Balance b/d (Opening Term Loan) | F15: 0
B16: To Balance c/d (Closing Term Loan Balance) | C16: =F15+F16-C15 -> 0 | E16: By Fresh Term Loan Received during year | F16: 0
B17: Total Debit: | C17: =SUM(C15:C16) -> 0 | E17: Total Credit: | F17: =SUM(F15:F16) -> 0
A19: Short-Term Borrowings (Bank OD / CC / Facility Ledger) (Note 5B)
A20: Dr. (Debit Side) | D20: Cr. (Credit Side)
A21: Date | B21: Particulars (Debit) | C21: Amount (₹) | D21: Date | E21: Particulars (Credit) | F21: Amount (₹)
B22: To Repayment / Credit during year | C22: 0 | E22: By Balance b/d (Opening Facility Balance) | F22: 0
B23: To Balance c/d (Closing Short-Term Borrowing Balance) | C23: =F22+F23-C22 -> 0 | E23: By Drawdown / Utilization during year | F23: 0
B24: Total Debit: | C24: =SUM(C22:C23) -> 0 | E24: Total Credit: | F24: =SUM(F22:F23) -> 0
A26: Trade Payables (Sundry Creditors Ledger) (Note 9)
A27: Dr. (Debit Side) | D27: Cr. (Credit Side)
A28: Date | B28: Particulars (Debit) | C28: Amount (₹) | D28: Date | E28: Particulars (Credit) | F28: Amount (₹)
B29: To Payments made to Suppliers | C29: 0 | E29: By Balance b/d (Opening Creditors) | F29: 0
B30: To Balance c/d (Closing Sundry Creditors) | C30: =F29+F30-C29 -> 0 | E30: By Credit Purchases during year (from PL_Notes) | F30: =PL_Notes!D12 -> 0
B31: Total Debit: | C31: =SUM(C29:C30) -> 0 | E31: Total Credit: | F31: =SUM(F29:F30) -> 0
A33: Other Current Liabilities Ledger (Note 10)
A34: Dr. (Debit Side) | D34: Cr. (Credit Side)
A35: Date | B35: Particulars (Debit) | C35: Amount (₹) | D35: Date | E35: Particulars (Credit) | F35: Amount (₹)
B36: To Payment of Statutory Dues & Expenses | C36: 0 | E36: By Balance b/d (Opening Liabilities / Accruals) | F36: 0
B37: To Balance c/d (Closing Other Current Liabilities) | C37: =F36+F37-C36 -> 0 | E37: By Accruals (GST, TDS & Expenses Payable) | F37: 0
B38: Total Debit: | C38: =SUM(C36:C37) -> 0 | E38: Total Credit: | F38: =SUM(F36:F37) -> 0
A40: Property, Plant and Equipment (PPE Ledger) (Note 11)
A41: Dr. (Debit Side) | D41: Cr. (Credit Side)
A42: Date | B42: Particulars (Debit) | C42: Amount (₹) | D42: Date | E42: Particulars (Credit) | F42: Amount (₹)
B43: To Balance b/d (Opening Net Block) | C43: 0 | E43: By Depreciation for the year (from Statement of P&L) | F43: =Statement_of_P&L!D12 -> #NAME?
B44: To Capital Additions / Purchases (Fixed Assets) | C44: 0 | E44: By Disposals / Deductions during year | F44: 0
E45: By Balance c/d (Closing Net Block to Balance Sheet) | F45: =C43+C44-F43-F44 -> #NAME?
B46: Total Debit: | C46: =SUM(C43:C45) -> 0 | E46: Total Credit: | F46: =SUM(F43:F45) -> #NAME?
...

Sheet PL_Notes
A1: =Setup_Control!C6 -> M/s. ABC Enterprises
A2: ="Statement of Profit and Loss Schedules & Registers for Financial Year Ended " & Setup_Control!C8 -> Statement of Profit and Loss Schedules & Registers for Financial Year Ended 31 March 2026
A4: Direct Purchases & Inward Material Costs (Note 21)
A5: Entry # | B5: Date | C5: Particulars / Description | D5: Amount (₹)
A6: 1 | D6: 0
A7: 2 | D7: 0
A8: 3 | D8: 0
A9: 4 | D9: 0
A10: 5 | D10: 0
A11: 6 | D11: 0
C12: Total Direct Purchases & Inward Material Costs (Flows to Statement of P&L): | D12: =SUM(D6:D11) -> 0
A14: Employee Benefits Expense (Note 22)
A15: Entry # | B15: Date | C15: Particulars / Description | D15: Amount (₹)
A16: 1 | D16: 0
A17: 2 | D17: 0
A18: 3 | D18: 0
A19: 4 | D19: 0
A20: 5 | D20: 0
A21: 6 | D21: 0
C22: Total Employee Benefits Expense (Flows to Statement of P&L): | D22: =SUM(D16:D21) -> 0
A24: Finance Costs (Note 23)
A25: Entry # | B25: Date | C25: Particulars / Description | D25: Amount (₹)
A26: 1 | D26: 0
A27: 2 | D27: 0
A28: 3 | D28: 0
A29: 4 | D29: 0
A30: 5 | D30: 0
A31: 6 | D31: 0
C32: Total Finance Costs (Flows to Statement of P&L): | D32: =SUM(D26:D31) -> 0
A34: Other Operating Expenses (Note 25)
A35: Entry # | B35: Date | C35: Particulars / Description | D35: Amount (₹)
A36: 1 | D36: 0
A37: 2 | D37: 0
A38: 3 | D38: 0
A39: 4 | D39: 0
A40: 5 | D40: 0
A41: 6 | D41: 0
C42: Total Other Operating Expenses (Flows to Statement of P&L): | D42: =SUM(D36:D41) -> 0
A44: Other Income (Note 20)
A45: Entry # | B45: Date | C45: Particulars / Description | D45: Amount (₹)
...

Sheet Cash_Flow_Statement
A1: =Setup_Control!C6 -> M/s. ABC Enterprises
A2: ="Cash Flow Statement for the year ended " & Setup_Control!C8 & IF(Setup_Control!C9="Yes", " (Indirect Method as per AS-3)", " (Direct Method as per AS-3)") -> Cash Flow Statement for the year ended 31 March 2026 (Direct Method as per AS-3)
D3: ="(" & Setup_Control!C11 & ")" -> (Amount in ₹)
B4: Particulars | D4: =Setup_Control!C8 -> 31 March 2026 | E4: =IF(Setup_Control!C9="Yes", Setup_Control!C10, "")
A5: A. | B5: =IF(Setup_Control!C9="Yes", "CASH FLOWS FROM OPERATING ACTIVITIES (INDIRECT METHOD)", "CASH FLOWS FROM OPERATING ACTIVITIES (DIRECT METHOD)") -> CASH FLOWS FROM OPERATING ACTIVITIES (DIRECT METHOD)
B6: =IF(Setup_Control!C9="Yes", "Net Profit Before Tax (from Statement of P&L)", " Cash receipts from customers / sales turnover") -> Cash receipts from customers / sales turnover | D6: =IF(Setup_Control!C9="Yes", Statement_of_P&L!D17, BS_Notes!C73) -> 0 | E6: =IF(Setup_Control!C9="Yes", Statement_of_P&L!E17, "")
B7: =IF(Setup_Control!C9="Yes", " Add: Depreciation and amortization expense", " Cash receipts from other operating revenue / income") -> Cash receipts from other operating revenue / income | D7: =IF(Setup_Control!C9="Yes", Statement_of_P&L!D12, BS_Notes!C74) -> #NAME? | E7: =IF(Setup_Control!C9="Yes", Statement_of_P&L!E12, "")
B8: =IF(Setup_Control!C9="Yes", " Add: Finance costs / Interest expense", " Less: Cash paid to suppliers for goods and services") -> Less: Cash paid to suppliers for goods and services | D8: =IF(Setup_Control!C9="Yes", Statement_of_P&L!D11, -BS_Notes!F72) -> 0 | E8: =IF(Setup_Control!C9="Yes", Statement_of_P&L!E11, "")
B9: =IF(Setup_Control!C9="Yes", " Less: Interest / Non-Operating income", " Less: Cash paid to and on behalf of employees") -> Less: Cash paid to and on behalf of employees | D9: =IF(Setup_Control!C9="Yes", -Statement_of_P&L!D6, -BS_Notes!F73) -> #NAME? | E9: =IF(Setup_Control!C9="Yes", -Statement_of_P&L!E6, "")
B10: =IF(Setup_Control!C9="Yes", "Operating Profit before Working Capital changes", " Less: Cash paid for other operating expenses") -> Less: Cash paid for other operating expenses | D10: =IF(Setup_Control!C9="Yes", SUM(D6:D9), -BS_Notes!F74) -> #NAME? | E10: =IF(Setup_Control!C9="Yes", SUM(E6:E9), "")
B11: =IF(Setup_Control!C9="Yes", " (Increase) / Decrease in Inventories", "Cash Generated from Operations") -> Cash Generated from Operations | D11: =IF(Setup_Control!C9="Yes", -(BS_Notes!F59-0), SUM(D6:D10)) -> #NAME? | E11: =IF(Setup_Control!C9="Yes", 0, "")
B12: =IF(Setup_Control!C9="Yes", " (Increase) / Decrease in Trade Receivables", "Less: Direct Income Taxes Paid") -> Less: Direct Income Taxes Paid | D12: =IF(Setup_Control!C9="Yes", -(BS_Notes!F66-0), -BS_Notes!C8) -> 0 | E12: =IF(Setup_Control!C9="Yes", 0, "")
B13: =IF(Setup_Control!C9="Yes", " (Increase) / Decrease in Short-term Loans & Advances", "") | D13: =IF(Setup_Control!C9="Yes", -(BS_Notes!F85-0), 0) -> 0 | E13: =IF(Setup_Control!C9="Yes", 0, "")
B14: =IF(Setup_Control!C9="Yes", " Increase / (Decrease) in Trade Payables", "") | D14: =IF(Setup_Control!C9="Yes", BS_Notes!C30-0, 0) -> 0 | E14: =IF(Setup_Control!C9="Yes", 0, "")
B15: =IF(Setup_Control!C9="Yes", " Increase / (Decrease) in Other Current Liabilities", "") | D15: =IF(Setup_Control!C9="Yes", BS_Notes!C37-0, 0) -> 0 | E15: =IF(Setup_Control!C9="Yes", 0, "")
B16: =IF(Setup_Control!C9="Yes", "Cash Generated from Operations", "") | D16: =IF(Setup_Control!C9="Yes", SUM(D10:D15), 0) -> 0 | E16: =IF(Setup_Control!C9="Yes", SUM(E10:E15), "")
B17: =IF(Setup_Control!C9="Yes", "Less: Direct Income Taxes Paid", "") | D17: =IF(Setup_Control!C9="Yes", -BS_Notes!C8, 0) -> 0 | E17: =IF(Setup_Control!C9="Yes", 0, "")
B18: Net Cash Flow from Operating Activities (A) | D18: =IF(Setup_Control!C9="Yes", D16+D17, D11+D12) -> #NAME? | E18: =IF(Setup_Control!C9="Yes", E16+E17, "")
A19: B. | B19: CASH FLOWS FROM INVESTING ACTIVITIES
B20: Purchase of Property, Plant & Equipment (Additions) | D20: =-(BS_Notes!C44) -> 0 | E20: =IF(Setup_Control!C9="Yes", 0, "")
B21: Interest / Non-Operating Income received | D21: =Statement_of_P&L!D6 -> #NAME? | E21: =IF(Setup_Control!C9="Yes", Statement_of_P&L!E6, "")
B22: Net Cash Flow from / (used in) Investing Activities (B) | D22: =SUM(D20:D21) -> #NAME? | E22: =IF(Setup_Control!C9="Yes", SUM(E20:E21), "")
A23: C. | B23: CASH FLOWS FROM FINANCING ACTIVITIES
B24: Additional Capital introduced by Owner | D24: =BS_Notes!F8 -> 0 | E24: =IF(Setup_Control!C9="Yes", 0, "")
B25: Drawings by Owner during the year | D25: =-BS_Notes!C7 -> 0 | E25: =IF(Setup_Control!C9="Yes", 0, "")
B26: Proceeds / (Repayment) of Long-term Borrowings | D26: =BS_Notes!C16-0 -> 0 | E26: =IF(Setup_Control!C9="Yes", 0, "")
B27: Net Proceeds / (Repayment) of Short-term Borrowings | D27: =BS_Notes!C23-0 -> 0 | E27: =IF(Setup_Control!C9="Yes", 0, "")
B28: Finance costs / Interest paid | D28: =-Statement_of_P&L!D11 -> #NAME? | E28: =IF(Setup_Control!C9="Yes", -Statement_of_P&L!E11, "")
B29: Net Cash Flow from / (used in) Financing Activities (C) | D29: =SUM(D24:D28) -> #NAME? | E29: =IF(Setup_Control!C9="Yes", SUM(E24:E28), "")
B30: NET INCREASE / (DECREASE) IN CASH & CASH EQUIVALENTS (A+B+C) | D30: =D18+D22+D29 -> #NAME? | E30: =IF(Setup_Control!C9="Yes", E18+E22+E29, "")
B31: Cash & Cash Equivalents at Beginning of Year (Opening Ledger) | D31: =BS_Notes!C72 -> 0 | E31: =IF(Setup_Control!C9="Yes", 0, "")
B32: Cash & Cash Equivalents at End of Year (Closing Ledger) | D32: =D30+D31 -> #NAME? | E32: =IF(Setup_Control!C9="Yes", E30+E31, "")
B34: CASH FLOW RECONCILIATION CHECK: | D34: =IF(ROUND(D32-BS_Notes!F78,2)=0,"MATCHED WITH BALANCE SHEET ✓","DIFF: " & TEXT(D32-BS_Notes!F78,"#,##0.00")) -> #NAME? | E34: =IF(Setup_Control!C9="Yes", IF(ROUND(E32-0,2)=0,"MATCHED WITH BALANCE SHEET ✓","DIFF: " & TEXT(E32-0,"#,##0.00")), "")
